<robot name="twip">
    <link name="body">
        <visual>
            <origin xyz="0 0 0" rpy="0 -0 0" />
            <geometry>
                <mesh filename="meshes/body_visual.stl" />
            </geometry>
            <material name="body_material">
                <color rgba="0.836159 0.803167 0.618468 1.0" />
            </material>
        </visual>
        <collision>
            <origin xyz="0 0 0" rpy="0 -0 0" />
            <geometry>
                <mesh filename="meshes/body_collision.stl" />
            </geometry>
            <material name="body_material">
                <color rgba="0.5 0.5 0.5 1.0" />
            </material>
        </collision>
        <inertial>
            <origin xyz="-0.0826102 -0.0762618 0.0883732" rpy="0 0 0" />
            <mass value="2.24123" />
            <inertia ixx="0.0305626" ixy="8.49821e-05" ixz="-0.00052591" iyy="0.0378459" iyz="-7.78686e-05" izz="0.0115403" />
        </inertial>
    </link>

    <link name="left_wheel">
        <visual>
            <origin xyz="0 0 0" rpy="0 -0 0" />
            <geometry>
                <mesh filename="meshes/left_wheel_visual.stl" />
            </geometry>
            <material name="left_wheel_material">
                <color rgba="0.701961 0.701961 0.701961 1.0" />
            </material>
        </visual>
        <collision>
            <origin xyz="0 0 0" rpy="0 -0 0" />
            <geometry>
                <mesh filename="meshes/left_wheel_collision.stl" />
            </geometry>
            <material name="left_wheel_material">
                <color rgba="0.5 0.5 0.5 1.0" />
            </material>
        </collision>
        <inertial>
            <origin xyz="-3.71533e-18 0 -0.014" rpy="0 0 0" />
            <mass value="0.190998" />
            <inertia ixx="0.000227519" ixy="-2.48322e-45" ixz="1.98553e-36" iyy="0.000435834" iyz="-9.62881e-37" izz="0.000227519" />
        </inertial>
    </link>

    <joint name="lwheel" type="revolute">
        <origin xyz="0.0509238 -0.0784359 -0.0289244" rpy="-3.14159 1.5708 0" />
        <parent link="body" />
        <child link="left_wheel" />
        <axis xyz="0 0 1" />
        <limit effort="1" velocity="20" />
        <dynamics friction="0.0" damping="600." stiffness="0.0"/>
    </joint>

    <link name="right_wheel">
        <visual>
            <origin xyz="0 0 0" rpy="0 -0 0" />
            <geometry>
                <mesh filename="meshes/right_wheel_visual.stl" />
            </geometry>
            <material name="right_wheel_material">
                <color rgba="0.701961 0.701961 0.701961 1.0" />
            </material>
        </visual>
        <collision>
            <origin xyz="0 0 0" rpy="0 -0 0" />
            <geometry>
                <mesh filename="meshes/right_wheel_collision.stl" />
            </geometry>
            <material name="right_wheel_material">
                <color rgba="0.5 0.5 0.5 1.0" />
            </material>
        </collision>
        <inertial>
            <origin xyz="-3.71533e-18 0 -0.014" rpy="0 0 0" />
            <mass value="0.190998" />
            <inertia ixx="0.000227519" ixy="-1.1483e-46" ixz="1.40219e-36" iyy="0.000435834" iyz="1.67541e-35" izz="0.000227519" />
        </inertial>
    </link>

    <joint name="rwheel" type="revolute">
        <origin xyz="-0.219373 -0.078494 -0.0289244" rpy="1.66533e-16 1.5708 0" />
        <parent link="body" />
        <child link="right_wheel" />
        <axis xyz="0 0 -1" />
        <limit effort="1" velocity="20" />
        <dynamics friction="0.0" damping="600." stiffness="0.0" />
    </joint>


</robot>
